// Mistake 1: Sending a response after find()
const result = await usermodel.find();
res.send({
  isSuccessfull: true,
  data: result,
});

// Mistake 2: Sending another response after save()
await UserObj.save()
  .then((result) => {
    res.status(201).send({
      isSuccessfull: true,
      data: result,
    });
  })
  .catch((err) => {
    res.status(400).send({
      isSuccessfull: false,
      data: null,
      error: err,
    });
  });
